✅ Resultado: {'error_msg': 'Not Found. Please check the configuration.'}
✅ Resultado: {'error_msg': 'Not Found. Please check the configuration.'}
Traceback (most recent call last):
  File "/usr/lib/python3.9/site-packages/urllib3/connectionpool.py", line 699, in urlopen
    httplib_response = self._make_request(
  File "/usr/lib/python3.9/site-packages/urllib3/connectionpool.py", line 445, in _make_request
    six.raise_from(e, None)
  File "<string>", line 3, in raise_from
  File "/usr/lib/python3.9/site-packages/urllib3/connectionpool.py", line 440, in _make_request
    httplib_response = conn.getresponse()
  File "/usr/lib/python3.9/http/client.py", line 1377, in getresponse
    response.begin()
  File "/usr/lib/python3.9/http/client.py", line 320, in begin
    version, status, reason = self._read_status()
  File "/usr/lib/python3.9/http/client.py", line 289, in _read_status
    raise RemoteDisconnected("Remote end closed connection without"
http.client.RemoteDisconnected: Remote end closed connection without response

During handling of the above exception, another exception occurred:

Traceback (most recent call last):
  File "/usr/lib/python3.9/site-packages/requests/adapters.py", line 439, in send
    resp = conn.urlopen(
  File "/usr/lib/python3.9/site-packages/urllib3/connectionpool.py", line 755, in urlopen
    retries = retries.increment(
  File "/usr/lib/python3.9/site-packages/urllib3/util/retry.py", line 532, in increment
    raise six.reraise(type(error), error, _stacktrace)
  File "/usr/lib/python3.9/site-packages/urllib3/packages/six.py", line 769, in reraise
    raise value.with_traceback(tb)
  File "/usr/lib/python3.9/site-packages/urllib3/connectionpool.py", line 699, in urlopen
    httplib_response = self._make_request(
  File "/usr/lib/python3.9/site-packages/urllib3/connectionpool.py", line 445, in _make_request
    six.raise_from(e, None)
  File "<string>", line 3, in raise_from
  File "/usr/lib/python3.9/site-packages/urllib3/connectionpool.py", line 440, in _make_request
    httplib_response = conn.getresponse()
  File "/usr/lib/python3.9/http/client.py", line 1377, in getresponse
    response.begin()
  File "/usr/lib/python3.9/http/client.py", line 320, in begin
    version, status, reason = self._read_status()
  File "/usr/lib/python3.9/http/client.py", line 289, in _read_status
    raise RemoteDisconnected("Remote end closed connection without"
urllib3.exceptions.ProtocolError: ('Connection aborted.', RemoteDisconnected('Remote end closed connection without response'))

During handling of the above exception, another exception occurred:

Traceback (most recent call last):
  File "/root/iag_z_service.py", line 19, in <module>
    resultado = procesar_solicitud()  
  File "/root/iag_z_service.py", line 7, in procesar_solicitud
    response = requests.post(  
  File "/usr/lib/python3.9/site-packages/requests/api.py", line 119, in post
    return request('post', url, data=data, json=json, **kwargs)
  File "/usr/lib/python3.9/site-packages/requests/api.py", line 61, in request
    return session.request(method=method, url=url, **kwargs)
  File "/usr/lib/python3.9/site-packages/requests/sessions.py", line 542, in request
    resp = self.send(prep, **send_kwargs)
  File "/usr/lib/python3.9/site-packages/requests/sessions.py", line 655, in send
    r = adapter.send(request, **kwargs)
  File "/usr/lib/python3.9/site-packages/requests/adapters.py", line 498, in send
    raise ConnectionError(err, request=request)
requests.exceptions.ConnectionError: ('Connection aborted.', RemoteDisconnected('Remote end closed connection without response'))
